Workbook

Sheet 试配表 (3)
A1: ( 中心 )试验室试配表
A2: 试验目的 | C2: 近期锂渣对混凝土工作性能影响 | I2: 每盘体积 | L2: 15 | M2: L
A3: 试配时间 | B3: 20260408 | C3: 温度 | D3: 22℃ | F3: 湿度 | I3: 试配编号
A4: 原材料种类 | B4: 规格 | D4: 生产厂家 | F4: 取样时间 | H4: 取样地点 | J4: 关键指标 | L4: 关键指标
A5: 水泥 | B5: PO42.5R | D5: 拉法基 | H5: 西站 | J5: 3d强度 | L5: 28d强度
A6: 矿粉 | B6: S95 | D6: 双实建材 | H6: 西站 | J6: 流动度比 | L6: 28d活性
A7: 复合灰 | D7: 拉法基 | H7: 西站 | J7: 需水量比 | L7: 28d活性
A8: 砂1 | B8: 细砂 | D8: 清砂 | J8: 细度模数 | L8: 含粉量
A9: 砂2 | B9: 粗砂 | D9: 拉法基 | J9: 细度模数 | L9: 含粉量
A10: 砂3
A11: 减水剂 | B11: SSJS-标准型 | D11: 常青藤
A12: 试样编号 | B12: 20260408-1 | D12: 20260408-2 | F12: 20260408-3
A13: 备注 | B13: 基准（矿粉＋复合粉） | D13: 5号仓锂渣 | F13: 1.23号技术部留样锂渣
A14: 项目 | B14: 每方 | C14: 每盘 | D14: 每方 | E14: 每盘 | F14: 每方 | G14: 每盘
A15: 设计用水量 | B15: 165 | D15: 165 | F15: 165
A16: 实际用水 | B16: =B15+B24+B27+B33+B30+B21-B23-B32-B26-B29-B35 -> 160.8 | C16: =B16*$L$2/1000 -> 2.412 | D16: =D15+D24+D27+D33+D30+D21-D23-D32-D26-D29-D35 -> 128.4 | E16: =D16*'试配表 (3)'!$L$2/1000 -> 1.926 | F16: =F15+F24+F27+F33+F30+F21-F23-F32-F26-F29-F35 -> 131.1 | G16: =F16*$L$2/1000 -> 1.9665
A17: 总胶量 | B17: =B18+B19+B20+B21 -> 320 | C17: =B17*$L$2/1000 -> 4.8 | D17: =D18+D19+D20+D21 -> 356 | E17: =D17*'试配表 (3)'!$L$2/1000 -> 5.34 | F17: =F18+F19+F20+F21 -> 356 | G17: =F17*$L$2/1000 -> 5.34
A18: 水泥 | B18: 210 | C18: =B18*$L$2/1000 -> 3.15 | D18: 206 | E18: =D18*'试配表 (3)'!$L$2/1000 -> 3.09 | F18: 206 | G18: =F18*$L$2/1000 -> 3.09
A19: 矿粉 | B19: 50 | C19: =B19*$L$2/1000 -> 0.75 | D19: 0 | E19: =D19*'试配表 (3)'!$L$2/1000 -> 0 | F19: 0 | G19: =F19*$L$2/1000 -> 0
A20: 复合掺合料 | B20: 60 | C20: =B20*$L$2/1000 -> 0.9 | D20: 60 | E20: =D20*'试配表 (3)'!$L$2/1000 -> 0.9 | F20: 60 | G20: =F20*$L$2/1000 -> 0.9
A21: 锂渣粉干重 | B21: 0 | C21: =B21*$L$2/1000 -> 0 | D21: 90 | E21: =D21*'试配表 (3)'!$L$2/1000 -> 1.35 | F21: 90 | G21: =F21*$L$2/1000 -> 1.35
A22: 锂渣粉含水 | B22: 0 | D22: 0.36 | F22: 0.33
A23: 锂渣粉湿重 | B23: =B21*B22+B21 -> 0 | C23: =B23*$L$2/1000 -> 0 | D23: =D21*D22+D21 -> 122.4 | E23: =D23*'试配表 (3)'!$L$2/1000 -> 1.836 | F23: =F21*F22+F21 -> 119.7 | G23: =F23*$L$2/1000 -> 1.7955
A24: 砂1干重 | B24: 210 | C24: =B24*$L$2/1000 -> 3.15 | D24: 210 | E24: =D24*'试配表 (3)'!$L$2/1000 -> 3.15 | F24: 210 | G24: =F24*$L$2/1000 -> 3.15
A25: 砂1含水率 | B25: 0.02 | D25: 0.02 | F25: 0.02
A26: 砂1湿重 | B26: =B24*B25+B24 -> 214.2 | C26: =B26*$L$2/1000 -> 3.213 | D26: =D24*D25+D24 -> 214.2 | E26: =D26*'试配表 (3)'!$L$2/1000 -> 3.213 | F26: =F24*F25+F24 -> 214.2 | G26: =F26*$L$2/1000 -> 3.213
A27: 砂2干重 | B27: 630 | C27: =B27*$L$2/1000 -> 9.45 | D27: 630 | E27: =D27*'试配表 (3)'!$L$2/1000 -> 9.45 | F27: 630 | G27: =F27*$L$2/1000 -> 9.45
A28: 砂2含水率 | B28: 0 | D28: 0 | F28: 0
A29: 砂2湿重 | B29: =B27*B28+B27 -> 630 | C29: =B29*$L$2/1000 -> 9.45 | D29: =D27*D28+D27 -> 630 | E29: =D29*'试配表 (3)'!$L$2/1000 -> 9.45 | F29: =F27*F28+F27 -> 630 | G29: =F29*$L$2/1000 -> 9.45
A30: 砂3干重 | B30: 0 | C30: =B30*$K$2/1000 -> 0 | D30: 0 | E30: =D30*'试配表 (3)'!$K$2/1000 -> 0 | F30: 0 | G30: =F30*$K$2/1000 -> 0
A31: 砂3含水率 | B31: 0 | D31: 0 | F31: 0
A32: 砂3湿重 | B32: =B30*B31+B30 -> 0 | C32: =B32*L2/1000 -> 0 | D32: =D30*D31+D30 -> 0 | E32: =D32*'试配表 (3)'!$K$2/1000 -> 0 | F32: =F30*F31+F30 -> 0 | G32: =F32*$K$2/1000 -> 0
A33: 碎石干重 | B33: 1040 | C33: =B33*$L$2/1000 -> 15.6 | D33: 1040 | E33: =D33*'试配表 (3)'!$L$2/1000 -> 15.6 | F33: 1040 | G33: =F33*$L$2/1000 -> 15.6
A34: 碎石含水率 | B34: 0 | D34: 0 | F34: 0
A35: 碎石湿重 | B35: =B34*B33+B33 -> 1040 | C35: =B35*$L$2/1000 -> 15.6 | D35: =D34*D33+D33 -> 1040 | E35: =D35*'试配表 (3)'!$L$2/1000 -> 15.6 | F35: =F34*F33+F33 -> 1040 | G35: =F35*$L$2/1000 -> 15.6
A36: 减水剂掺量 | B36: 0.018 | D36: 0.018 | F36: 0.018
A37: 减水剂用量 | B37: =B36*B17 -> 5.76 | C37: =B37*$L$2 -> 86.4 | D37: =D36*D17 -> 6.408 | E37: =D37*'试配表 (3)'!$L$2 -> 96.12 | F37: =F36*F17 -> 6.408 | G37: =F37*$L$2 -> 96.12
A38: 减水剂实际掺量、用量 | B38: 0.016 | D38: 0.021 | F38: 0.0195
A39: 砂率 | B39: =(B24+B27+B30)/(B24+B27+B30+B33) -> 0.44680851 | D39: =(D24+D27+D30)/(D24+D27+D30+D33) -> 0.44680851 | F39: =(F24+F27+F30)/(F24+F27+F30+F33) -> 0.44680851
A40: 水胶比 | B40: =B15/B17 -> 0.515625 | D40: =D15/D17 -> 0.46348315 | F40: =F15/F17 -> 0.46348315
...
